Traceback (most recent call last):
  File "/opt/hostedtoolcache/Python/3.8.8/x64/lib/python3.8/site-packages/jupyter_cache/executors/utils.py", line 51, in single_nb_execution
    executenb(
  File "/opt/hostedtoolcache/Python/3.8.8/x64/lib/python3.8/site-packages/nbclient/client.py", line 1112, in execute
    return NotebookClient(nb=nb, resources=resources, km=km, **kwargs).execute()
  File "/opt/hostedtoolcache/Python/3.8.8/x64/lib/python3.8/site-packages/nbclient/util.py", line 74, in wrapped
    return just_run(coro(*args, **kwargs))
  File "/opt/hostedtoolcache/Python/3.8.8/x64/lib/python3.8/site-packages/nbclient/util.py", line 53, in just_run
    return loop.run_until_complete(coro)
  File "/opt/hostedtoolcache/Python/3.8.8/x64/lib/python3.8/asyncio/base_events.py", line 616, in run_until_complete
    return future.result()
  File "/opt/hostedtoolcache/Python/3.8.8/x64/lib/python3.8/site-packages/nbclient/client.py", line 553, in async_execute
    await self.async_execute_cell(
  File "/opt/hostedtoolcache/Python/3.8.8/x64/lib/python3.8/site-packages/nbclient/client.py", line 857, in async_execute_cell
    self._check_raise_for_error(cell, exec_reply)
  File "/opt/hostedtoolcache/Python/3.8.8/x64/lib/python3.8/site-packages/nbclient/client.py", line 760, in _check_raise_for_error
    raise CellExecutionError.from_cell_and_msg(cell, exec_reply_content)
nbclient.exceptions.CellExecutionError: An error occurred while executing the following cell:
------------------
@magicgui(call_button='Add Image')
def my_widget(ny: int=64, nx: int=64) -> Image:
  return Image(np.random.rand(ny, nx), name='My Image')

viewer = napari.Viewer()
viewer.window.add_dock_widget(my_widget, area='right')
my_widget()  # "call the widget" to call the function.
             # Normally this would be caused by some user UI interaction
------------------

[0;31m---------------------------------------------------------------------------[0m
[0;31mTypeError[0m                                 Traceback (most recent call last)
[0;32m~/work/napari/napari/main/napari/_qt/qt_main_window.py[0m in [0;36mshow[0;34m(self)[0m
[1;32m   1096[0m                     self._qt_window._set_window_settings(
[0;32m-> 1097[0;31m                         [0;34m*[0m[0mself[0m[0;34m.[0m[0m_qt_window[0m[0;34m.[0m[0m_load_window_settings[0m[0;34m([0m[0;34m)[0m[0;34m[0m[0;34m[0m[0m
[0m[1;32m   1098[0m                     )

[0;32m~/work/napari/napari/main/napari/_qt/qt_main_window.py[0m in [0;36m_load_window_settings[0;34m(self)[0m
[1;32m     77[0m         [0;31m# It's necessary to verify if the window/position value is valid with the current screen.[0m[0;34m[0m[0;34m[0m[0;34m[0m[0m
[0;32m---> 78[0;31m         [0mwidth[0m[0;34m,[0m [0mheight[0m [0;34m=[0m [0mwindow_position[0m[0;34m[0m[0;34m[0m[0m
[0m[1;32m     79[0m         [0mscreen_shape[0m [0;34m=[0m [0mQApplication[0m[0;34m.[0m[0mdesktop[0m[0;34m([0m[0;34m)[0m[0;34m.[0m[0mgeometry[0m[0;34m([0m[0;34m)[0m[0;34m[0m[0;34m[0m[0m

[0;31mTypeError[0m: cannot unpack non-iterable NoneType object

During handling of the above exception, another exception occurred:

[0;31mKeyError[0m                                  Traceback (most recent call last)
[0;32m<ipython-input-4-fb66e7788f4d>[0m in [0;36m<module>[0;34m[0m
[1;32m      3[0m   [0;32mreturn[0m [0mImage[0m[0;34m([0m[0mnp[0m[0;34m.[0m[0mrandom[0m[0;34m.[0m[0mrand[0m[0;34m([0m[0mny[0m[0;34m,[0m [0mnx[0m[0;34m)[0m[0;34m,[0m [0mname[0m[0;34m=[0m[0;34m'My Image'[0m[0;34m)[0m[0;34m[0m[0;34m[0m[0m
[1;32m      4[0m [0;34m[0m[0m
[0;32m----> 5[0;31m [0mviewer[0m [0;34m=[0m [0mnapari[0m[0;34m.[0m[0mViewer[0m[0;34m([0m[0;34m)[0m[0;34m[0m[0;34m[0m[0m
[0m[1;32m      6[0m [0mviewer[0m[0;34m.[0m[0mwindow[0m[0;34m.[0m[0madd_dock_widget[0m[0;34m([0m[0mmy_widget[0m[0;34m,[0m [0marea[0m[0;34m=[0m[0;34m'right'[0m[0;34m)[0m[0;34m[0m[0;34m[0m[0m
[1;32m      7[0m [0mmy_widget[0m[0;34m([0m[0;34m)[0m  [0;31m# "call the widget" to call the function.[0m[0;34m[0m[0;34m[0m[0m

[0;32m~/work/napari/napari/main/napari/viewer.py[0m in [0;36m__init__[0;34m(self, title, ndisplay, order, axis_labels, show)[0m
[1;32m     50[0m         [0;32mfrom[0m [0;34m.[0m[0mwindow[0m [0;32mimport[0m [0mWindow[0m[0;34m[0m[0;34m[0m[0m
[1;32m     51[0m [0;34m[0m[0m
[0;32m---> 52[0;31m         [0mself[0m[0;34m.[0m[0m_window[0m [0;34m=[0m [0mWindow[0m[0;34m([0m[0mself[0m[0;34m,[0m [0mshow[0m[0;34m=[0m[0mshow[0m[0;34m)[0m[0;34m[0m[0;34m[0m[0m
[0m[1;32m     53[0m [0;34m[0m[0m
[1;32m     54[0m     [0;31m# Expose private window publically. This is needed to keep window off pydantic model[0m[0;34m[0m[0;34m[0m[0;34m[0m[0m

[0;32m~/work/napari/napari/main/napari/_qt/qt_main_window.py[0m in [0;36m__init__[0;34m(self, viewer, show)[0m
[1;32m    300[0m [0;34m[0m[0m
[1;32m    301[0m         [0;32mif[0m [0mshow[0m[0;34m:[0m[0;34m[0m[0;34m[0m[0m
[0;32m--> 302[0;31m             [0mself[0m[0;34m.[0m[0mshow[0m[0;34m([0m[0;34m)[0m[0;34m[0m[0;34m[0m[0m
[0m[1;32m    303[0m [0;34m[0m[0m
[1;32m    304[0m     [0;32mdef[0m [0m__getattr__[0m[0;34m([0m[0mself[0m[0;34m,[0m [0mname[0m[0;34m)[0m[0;34m:[0m[0;34m[0m[0;34m[0m[0m

[0;32m~/work/napari/napari/main/napari/_qt/qt_main_window.py[0m in [0;36mshow[0;34m(self)[0m
[1;32m   1101[0m [0;34m[0m[0m
[1;32m   1102[0m                 warnings.warn(
[0;32m-> 1103[0;31m                     trans._(
[0m[1;32m   1104[0m                         [0;34m"The window geometry settings could not be "[0m[0;34m[0m[0;34m[0m[0m
[1;32m   1105[0m                         [0;34m"loaded due to the following error: {err}"[0m[0;34m[0m[0;34m[0m[0m

[0;32m~/work/napari/napari/main/napari/utils/translations.py[0m in [0;36m_[0;34m(self, msgid, deferred, **kwargs)[0m
[1;32m    392[0m             )
[1;32m    393[0m             [0;32mif[0m [0mdeferred[0m[0;34m[0m[0;34m[0m[0m
[0;32m--> 394[0;31m             [0;32melse[0m [0mself[0m[0;34m.[0m[0m_dnpgettext[0m[0;34m([0m[0mmsgid[0m[0;34m=[0m[0mmsgid[0m[0;34m,[0m [0;34m**[0m[0mkwargs[0m[0;34m)[0m[0;34m[0m[0;34m[0m[0m
[0m[1;32m    395[0m         )
[1;32m    396[0m [0;34m[0m[0m

[0;32m~/work/napari/napari/main/napari/utils/translations.py[0m in [0;36m_dnpgettext[0;34m(self, msgctxt, msgid, msgid_plural, n, **kwargs)[0m
[1;32m    363[0m [0;34m[0m[0m
[1;32m    364[0m         [0mkwargs[0m[0;34m[[0m[0;34m'n'[0m[0;34m][0m [0;34m=[0m [0mn[0m[0;34m[0m[0;34m[0m[0m
[0;32m--> 365[0;31m         [0;32mreturn[0m [0mtranslation[0m[0;34m.[0m[0mformat[0m[0;34m([0m[0;34m**[0m[0mkwargs[0m[0;34m)[0m[0;34m[0m[0;34m[0m[0m
[0m[1;32m    366[0m [0;34m[0m[0m
[1;32m    367[0m     def _(

[0;31mKeyError[0m: 'err'
KeyError: 'err'

